Workbook
Name EDILE_NOMI: #REF!
Name EDILE_PERC: #REF!
Name PROG_NOMI: #REF!
Name PROG_PERC: #REF!
Name SICUREZZA_NOMI: #REF!
Name SICUREZZA_PERC: #REF!

Sheet Analisi preliminareTOTALI
A1: Riepilogo
F3: Data : 29/05/2025
A6: Dati Cliente
A8: Cliente caso 04
A9: Indirizzo
A10: Reggio Emilia (RE)
A17: RIEPILOGO TOTALI | H17: Celle correttive
B20: A-EDILE iva inclusa 10% | F20: ='A-EDILE'!G196 -> 92224
B22: B-FINITURE iva inclusa 22% | F22: ='B-FINITURE'!E82 -> 0
B24: C-PORTE E SERRAMENTI iva inclusa 10% | F24: ='C- SERRAMENTI PORTE '!E34 -> 0
B26: D-PRODOTTI iva inclusa 10% | F26: ='D- PRODOTTI'!E29 -> 0
F28: =(F22+F24+F26)*0.07 -> 0
A30: TOTALE iva inclusa | F30: =F20+F22+F24+F26+F28 -> 92224
B34: NOMINA DI CSE/CSP inclusa iva e contrubuti
B35: PRATICHE AMMINISTRATIVE inclusa iva e contrubuti
A36: TOTALE | F36: =F34++F35 -> 0
A38: da pagare iva INCLUSA | F38: =F36+F30 -> 92224
A43: FINANZIAMENTO
A44: PER TOTALE LAVORI TRA 25 E 50K | D44: n.RATE | E44: rata/mese
D45: 48 | E45: =F30/D45/2 -> 960.66667
A46: PER TOTALE LAVORI TRA 50K E 100K
D47: 60 | E47: =F30/D47/2 -> 768.53333
A49: Si informa che la divisione dei costi sopra elencati verrà sottoposta ad approvazione da parte del partner finanziario fiditalia

Sheet A-EDILE
C1: Computo | Elenco Lavorazioni
G2: ='Analisi preliminareTOTALI'!F3 -> Data : 29/05/2025
B4: Le voci di seguito riportate ed utilizzate nel computo, sono state redatte per l'individuazioni dei lavori da effettuare secondo progetto approvato. Le misure sono calcolate da disegno, eventuali differenze sono da considerare tolleranze progettuali. Si richiede alle imprese di verificare le lavorazioni e segnalare eventuali dimenticanze/discrepanze e/o migliorie.
B6: Dati Cliente
B8: ='Analisi preliminareTOTALI'!A8 -> Cliente caso 04
B9: ='Analisi preliminareTOTALI'!A9 -> Indirizzo
B10: ='Analisi preliminareTOTALI'!A10 -> Reggio Emilia (RE)
B11: ='Analisi preliminareTOTALI'!A11 -> 0
B12: ='Analisi preliminareTOTALI'!A12 -> 0
B13: ='Analisi preliminareTOTALI'!A13 -> 0
B15: DESCRIZIONE SINTETICA DELLE OPERE DA ESEGUIRE COMPUTATE DI SEGUITO
B16: Appartamento posto al primo piano di fabbricato plurifamiliare. Ristrutturazione Totale
C25: DESCRIZIONE | D25: UM: | E25: Qta: | F25: Prezzo U. | G25: Totale | J25: Listino | K25: TOTALE IMPRESA | L25: TOTALE IMPRESA | N25: Fee arch. | O25: Guadagno | P25: Percentuale
B26: A | C26: ALLESTIMENTO DI CANTIERE | H26: NOTE(non stampare mai) | J26: 0.65 | K26: Prezzo Unità | L26: Totale | M26: Sal gg
A27: EDILE | B27: A.1 | C27: Allestimento area di cantiere con protezione zone di passaggio a mezzo teli nylon e/o cartoni al fine di eseguire i lavori in oggetto a perfetta regola d'arte, a norma ed in sicurezza. Fornitura ed installazione cartello di cantiere, DPI lavoratori e POS. | D27: ac | E27: 1 | F27: 1500 | G27: =F27*E27 -> 1500 | H27: L'allestimento di cantire deve essere sempre presente e dovrà essere calcolata nel seguente modo: per appartamenti fino a 100 mq - 600 | K27: =F27*$J$26 -> 975 | L27: =E27*K27 -> 975 | N27: =G27*0.05 -> 75 | O27: =G27-L27-N27 -> 450 | P27: =O27/G27 -> 0.3
A28: ELETTRICO | B28: A.2 | C28: Installazione di quadro elettrico di cantiere effettuato da operatore abilitato, e rilascio della certificazioni di installazione e conformità valido per tutta la durata del cantiere. | D28: ac | E28: 1 | F28: 150 | G28: =F28*E28 -> 150 | H28: Il quadro mobile per cantiere deve essere presente. | K28: =F28*$J$26 -> 97.5 | L28: =E28*K28 -> 97.5 | N28: =G28*0.05 -> 7.5 | O28: =G28-L28-N28 -> 45 | P28: =O28/G28 -> 0.3
A29: EDILE | B29: A.3 | C29: Rimozione di apparecchi idro-termo-sanitari, incluso lo smontaggio delle apparecchiature, rubinetterie e degli accessori e chiusura delle adduzioni con tappi. Compreso il carico da piano strada e trasporto ad impianti di stoccaggio, di recupero o a discarica | H29: Questa voce deve essere presente nel caso di rifacimento di uno o più bagni
A30: EDILE | C30: a piatto doccia | D30: cad | E30: 2 | F30: 40 | G30: =F30*E30 -> 80 | K30: =F30*$J$26 -> 26 | L30: =E30*K30 -> 52 | N30: =G30*0.05 -> 4 | O30: =G30-L30-N30 -> 24 | P30: =O30/G30 -> 0.3
A31: EDILE | C31: b vasca da bagno | D31: cad | E31: 2 | F31: 40 | G31: =F31*E31 -> 80 | K31: =F31*$J$26 -> 26 | L31: =E31*K31 -> 52 | N31: =G31*0.05 -> 4 | O31: =G31-L31-N31 -> 24 | P31: =O31/G31 -> 0.3
A32: EDILE | C32: c vaso igienico (WC) | D32: cad | E32: 2 | F32: 40 | G32: =F32*E32 -> 80 | K32: =F32*$J$26 -> 26 | L32: =E32*K32 -> 52 | N32: =G32*0.05 -> 4 | O32: =G32-L32-N32 -> 24 | P32: =O32/G32 -> 0.3
A33: EDILE | C33: d bidet | D33: cad | E33: 2 | F33: 40 | G33: =F33*E33 -> 80 | K33: =F33*$J$26 -> 26 | L33: =E33*K33 -> 52 | N33: =G33*0.05 -> 4 | O33: =G33-L33-N33 -> 24 | P33: =O33/G33 -> 0.3
A34: EDILE | C34: e lavabo singolo su mensola | D34: cad | E34: 0 | F34: 40 | G34: =F34*E34 -> 0 | K34: =F34*$J$26 -> 26 | L34: =E34*K34 -> 0 | N34: =G34*0.05 -> 0 | O34: =G34-L34-N34 -> 0 | P34: =O34/G34 -> #DIV/0!
A35: EDILE | C35: f lavello da cucina in porcellana | D35: cad | E35: 0 | F35: 40 | G35: =F35*E35 -> 0 | K35: =F35*$J$26 -> 26 | L35: =E35*K35 -> 0 | N35: =G35*0.05 -> 0 | O35: =G35-L35-N35 -> 0 | P35: =O35/G35 -> #DIV/0!
A36: EDILE | C36: g scaldabagno elettrico | D36: cad | E36: 0 | F36: 40 | G36: =F36*E36 -> 0 | K36: =F36*$J$26 -> 26 | L36: =E36*K36 -> 0 | N36: =G36*0.05 -> 0 | O36: =G36-L36-N36 -> 0 | P36: =O36/G36 -> #DIV/0!
A37: EDILE | C37: h cassetta alta di scarico | D37: cad | E37: 0 | F37: 40 | G37: =F37*E37 -> 0 | K37: =F37*$J$26 -> 26 | L37: =E37*K37 -> 0 | N37: =G37*0.05 -> 0 | O37: =G37-L37-N37 -> 0 | P37: =O37/G37 -> #DIV/0!
A38: IDRAULICO | B38: A.4 | C38: Rimozione delle linee di alimentazione degli apparecchi igienicosanitari (linea acqua calda e linea acqua fredda) fino alle valvole di intercettazione e delle relative tubazioni di scarico fino alla colonna principale. Compresi i tagli, le intercettazioni, le opere provvisionali di sostegno e protezione. Compreso il carico da piano strada e trasporto ad impianti di stoccaggio, di recupero o a discarica. | D38: ac | E38: 1 | F38: 300 | G38: =F38*E38 -> 300 | H38: Questa voce deve essere presente nel caso di rifacimento di uno o più bagni. Dovrà essere computata una linea da rimuovere per ogni bagno da rifare. | K38: =F38*$J$26 -> 195 | L38: =E38*K38 -> 195 | N38: =G38*0.05 -> 15 | O38: =G38-L38-N38 -> 90 | P38: =O38/G38 -> 0.3
A39: EDILE | B39: A.5 | C39: Rimozione di tutte le porte interne comprese di anta, telaio e falso telaio con trasposto dal piano strada alle pubbliche discariche. Compreso il carico da piano strada e trasporto ad impianti di stoccaggio, di recupero o a discarica. | D39: cad | E39: 14 | F39: 50 | G39: =F39*E39 -> 700 | K39: =F39*$J$26 -> 32.5 | L39: =E39*K39 -> 455 | N39: =G39*0.05 -> 35 | O39: =G39-L39-N39 -> 210 | P39: =O39/G39 -> 0.3
A40: EDILE | B40: A.6 | C40: Rimozione dei corpi riscaldanti in alluminio e/o ghisa presenti all'interno dell'immobile.Compreso il carico da piano strada e trasporto ad impianti di stoccaggio, di recupero o a discarica.
A41: EDILE | C41: radiatori in ghisa e/o in alluminio:
A42: EDILE | C42: a fino a 15 elementi, per radiatore | D42: cad | E42: 8 | F42: 80 | G42: =F42*E42 -> 640 | K42: =F42*$J$26 -> 52 | L42: =E42*K42 -> 416 | N42: =G42*0.05 -> 32 | O42: =G42-L42-N42 -> 192 | P42: =O42/G42 -> 0.3
A43: EDILE | C43: b da 7 a 12 elementi, per radiatore | D43: cad | E43: 0 | F43: 51 | G43: =F43*E43 -> 0 | K43: =F43*$J$26 -> 33.15 | L43: =E43*K43 -> 0 | N43: =G43*0.05 -> 0 | O43: =G43-L43-N43 -> 0 | P43: =O43/G43 -> #DIV/0!
A44: EDILE | C44: c da 13 a 20 elementi, per radiatore | D44: cad | E44: 0 | F44: 51 | G44: =F44*E44 -> 0 | K44: =F44*$J$26 -> 33.15 | L44: =E44*K44 -> 0 | N44: =G44*0.05 -> 0 | O44: =G44-L44-N44 -> 0 | P44: =O44/G44 -> #DIV/0!
A45: IDRAULICO | B45: A.7 | C45: Rimozione di condizionatore autonomo monosplit costituito da motocondensante esterna e macchina interna, compreso l'onere del recupero gas e l'avvicinamento al luogo di deposito provvisorio in attesa di trasporto a discarica, esclusa la rimozione delle tubazioni di collegamento ed i cavi di alimentazione elettrica:
A46: IDRAULICO | C46: a macchina interna a parete alta o soffitto | D46: cad | E46: 0 | F46: 80 | G46: =F46*E46 -> 0 | K46: =F46*$J$26 -> 52 | L46: =E46*K46 -> 0 | N46: =G46*0.05 -> 0 | O46: =G46-L46-N46 -> 0 | P46: =O46/G46 -> #DIV/0!
A47: IDRAULICO | C47: b macchina interna a parete bassa o pavimento. | D47: cad | E47: 0 | F47: 80 | G47: =F47*E47 -> 0 | K47: =F47*$J$26 -> 52 | L47: =E47*K47 -> 0 | N47: =G47*0.05 -> 0 | O47: =G47-L47-N47 -> 0 | P47: =O47/G47 -> #DIV/0!
A48: EDILE | B48: A.8 | C48: Movimentazione nell'area di cantiere di materiali di risulta e assistenza con personale per il carico di tutte le forniture (quali ad esempio pavimenti, rivestimenti, sanitari, ecc.) esclusi gli infissi. Compresa l'immediata verifica degli stessi in riferimento alla corrispondenza di quantità e qualità riportate sui vari documenti di trasporto) per tutto il periodo di durata dei lavori. Si ritiene da verificare la possibilità di installare un argano e di parcheggiare il mezzo di trasporto ai piedi dell'argano. | D48: piano | E48: 1 | F48: 2000 | G48: =F48*E48 -> 2000 | H48: Questa voce deve essere presente. Il tecnico dovrà riportare nella formula il numero del piano (ad esempio: *1 se è piano primo, *2 se è piano secondo ecc). Si precisa che normalmente la consegna delle forniture è effettuata all’indirizzo indicato dal Cliente al termine del processo di acquisto, con scarico al piano terra del numero civico. Questa voce, pertanto, include: 1) la consegna delle forniture all’interno dell’abitazione del Cliente; 2) il controllo, al momento della consegna, del numero dei colli in consegna e dell'integrità dell’imballo; 3) movimentazione del materiale di risulta. | K48: =F48*$J$26 -> 1300 | L48: =E48*K48 -> 1300 | N48: =G48*0.05 -> 100 | O48: =G48-L48-N48 -> 600 | P48: =O48/G48 -> 0.3 | T48: CIRCA 2000-2500 APPP 100 MQ PIANO
B49: A | C49: TOTALE ALLESTIMENTO DI CANTIERE | G49: =SUM(G27:G48) -> 5610 | L49: =SUM(L27:L48) -> 3646.5 | N49: =SUM(N27:N48) -> 280.5 | O49: =SUM(O27:O48) -> 1683 | P49: =O49/F49 -> #DIV/0!
B51: A.1 | C51: DEMOLIZIONI - RIMOZIONI - TRASPORTO
A52: EDILE | B52: A.1.1 | C52: Demolizione di muratura di tamponamento e di tramezzi spessore da 8 a 12 cm, compresi intonaci, eseguita anche con l'ausilio di idonei mezzi. Compreso l’accatastamento nei siti che verranno indicati dalla Direzione dei lavori nell'ambito del cantiere. Compreso il carico da piano strada e trasporto ad impianti di stoccaggio, di recupero o a discarica. SECONDO PROGETTO
A53: EDILE | C53: a muratura in mattoni pieni | D53: mq | E53: 0 | F53: 42.5 | G53: =F53*E53 -> 0 | K53: =F53*$J$26 -> 27.625 | L53: =E53*K53 -> 0 | N53: =G53*0.05 -> 0 | O53: =G53-L53-N53 -> 0 | P53: =O53/G53 -> #DIV/0!
...

Sheet B-FINITURE
E3: ='Analisi preliminareTOTALI'!F3 -> Data : 29/05/2025
E4: Validità Preventivo: 15gg
A6: Dati Cliente
A8: ='Analisi preliminareTOTALI'!A8 -> Cliente caso 04
A9: ='Analisi preliminareTOTALI'!A9 -> Indirizzo
A10: ='Analisi preliminareTOTALI'!A10 -> Reggio Emilia (RE)
A11: ='Analisi preliminareTOTALI'!A11 -> 0
A12: ='Analisi preliminareTOTALI'!A12 -> 0
A13: ='Analisi preliminareTOTALI'!A13 -> 0
A16: DESCRIZIONE | B16: UM: | C16: Qta: | D16: Prezzo Unità | E16: Totale
A18: MATERIALI DI FINITURA
A19: PAVIMENTI E RIVESTIMENTI GRES
A20: Gres porcellanato colorato in massa in piastrelle rettificate, ottenute per pressatura, per pavimentazioni ad intenso calpestio, rispondenti alla norma UNI EN 14411, classe assorbimento acqua BIa UGL: effetto cemento, con superficie antiscivolo (R10 A):30 × 60 cm, naturale o bocciardato, spessore 10mm | B20: mq | C20: 0 | D20: 28.32 | E20: =D20*C20 -> 0
A21: Gres porcellanato colorato in massa in piastrelle rettificate, ottenute per pressatura, per pavimentazioni ad intenso calpestio, rispondenti alla norma UNI EN 14411, classe assorbimento acqua BIa UGL: effetto cemento, con superficie antiscivolo (R10 A): 60 × 60 cm, spessore 15 mm | B21: mq | C21: 0 | D21: 28.32 | E21: =D21*C21 -> 0
A22: Gres porcellanato colorato in massa in piastrelle rettificate, ottenute per pressatura, per pavimentazioni ad intenso calpestio, rispondenti alla norma UNI EN 14411, classe assorbimento acqua BIa UGL: effetto cemento, con superficie antiscivolo (R10 A): 60 × 120 cm, naturale, spessore 10 mm | B22: mq | C22: 0 | D22: 32.32 | E22: =D22*C22 -> 0
A23: Gres porcellanato smaltato in piastrelle, resistente agli sbalzi termici, al gelo e agli acidi, per pavimentazioni ad uso residenziale o terziario leggero, a norma UNI EN 14411 gruppo BIa GL: effetto pietra naturale, rettificato, antiscivolo (R9): 30 × 30 cm, disegno mosaico | B23: mq | C23: 0 | D23: 125 | E23: =D23*C23 -> 0
A24: Gres porcellanato smaltato in piastrelle, resistente agli sbalzi termici, al gelo e agli acidi, per pavimentazioni ad uso residenziale o terziario leggero, a norma UNI EN 14411 gruppo BIa GL:effetto marmo, antiscivolo (R9), spessore 9 mm:30 × 60 cm | B24: mq | C24: 0 | D24: 36.63 | E24: =D24*C24 -> 0
A25: Fornitura di pavimentazione/rivestimento in gres porcelanato TIPO: Padana marmosmart pietrasanta smart honed 60 x 60 1° sc. (mq. 1,44x) | B25: mq | C25: 0 | D25: 23.37 | E25: =D25*C25 -> 0
A26: Gres porcellanato colorato in massa in piastrelle rettificate, ottenute per pressatura, per pavimentazioni ad intenso calpestio, rispondenti alla norma UNI EN 14411, classe assorbimento acqua BIa UGL:effetto cemento, con superficie antiscivolo (R10 A):dimensioni 60 × 60 cm, spessore 15 mm | B26: mq | C26: 0 | D26: 28.32 | E26: =D26*C26 -> 0
A27: Gres porcellanato smaltato in piastrelle, resistente agli sbalzi termici, al gelo e agli acidi, per pavimentazioni ad uso residenziale o terziario leggero, a norma UNI EN 14411 gruppo BIa GL:effetto marmo, antiscivolo (R9), spessore 9 mm:60 × 120 cm | B27: mq | C27: 0 | D27: 38.78 | E27: =D27*C27 -> 0
A28: Gres porcellanato colorato in massa in piastrelle rettificate, ottenute per pressatura, per pavimentazioni ad intenso calpestio, rispondenti alla norma UNI EN 14411, classe assorbimento acqua BIa UGL:effetto cemento, con superficie antiscivolo (R10 A):60 × 120 cm, naturale, spessore 10 mm | B28: mq | C28: 0 | D28: 43.4 | E28: =D28*C28 -> 0
A29: Gres porcellanato smaltato in piastrelle, resistente agli sbalzi termici, al gelo e agli acidi, per pavimentazioni ad uso residenziale o terziario leggero, a norma UNI EN 14411 gruppo BIa GL: effetto pietra naturale, rettificato, antiscivolo (R9): 30 × 60 cm, spessore 10 mm | B29: mq | C29: 0 | D29: 28.32 | E29: =D29*C29 -> 0
A30: Gres porcellanato smaltato in piastrelle, resistente agli sbalzi termici, al gelo e agli acidi, per pavimentazioni ad uso residenziale o terziario leggero, a norma UNI EN 14411 gruppo BIa GL: effetto pietra naturale, rettificato, antiscivolo (R9): 30 × 60 cm, spessore 10 mm | B30: mq | C30: 0 | D30: 28.32 | E30: =D30*C30 -> 0
A31: Gres porcellanato smaltato in piastrelle, resistente agli sbalzi termici, al gelo e agli acidi, per pavimentazioni ad uso residenziale o terziario leggero, a norma UNI EN 14411 gruppo BIa GL: effetto pietra naturale, rettificato, antiscivolo (R9): 60 × 120 cm, spessore 10,5 mm | B31: mq | C31: 0 | D31: 46.9 | E31: =D31*C31 -> 0
... A41: Ceramica monocottura di pasta bianca in lastre ottenute per pressatura, rettificate, per rivestimenti ad uso residenziale, grado di assorbimento acqua gruppo BIII L a norma UNI EN 14411, delle dimensioni di 60 × 180 cm:effetto cemento, strutturato, spessore 9 mm | B41: mq | C41: 0 | D41: 76.3 | E41: =D41*C41 -> 0
A42: PAVIMENTI
A43: Gres porcellanato colorato in massa, ottenuto per pressatura, in lastre di bassissimo spessore rinforzate sul lato inferiore con rete in fibra di vetro, per pavimentazioni ad intenso calpestio, rispondenti alla norma UNI EN 14411, classe reazione al fuoco A2 - s1, classe assorbimento acqua Bia-UGL, nei seguenti formati: effetto legno, spessore 5 mm:20 × 120 cm | B43: mq | C43: 0 | D43: 79.1 | E43: =D43*C43 -> 0
A44: Vinilico multistrato LVT in listoni delle dimensioni di 17 ÷ 20 × 100 ÷ 124 cm o piastre delle dimensioni di 36 × 69 cm con profili laterali ad incastro per posa senza collante, con uno strato d'usura in pvc puro trasparente che protegge uno strato a motivi stampatitrattato con fotoreticolazione UV e laser, resistenza all'abrasione secondo norma EN 660-2 inferiore a 2 mm3 (gruppo T), classe di resistenza allo scivolamento R10 secondo EN 13893 e conforme al test BCRA, classe di reazione al fuoco Bfl-s1 secondo norma EN ISO 13501, isolamento acustico non inferiore a 4 dB secondo EN ISO 717-2, antibatterico secondo ISO 22196, con certificazione EPD e Floorscore/Leed - strato di usura di spessore 0,30 mm, spessore totale 4,50 mm, peso non superiore a 4,10 kg/m2 | B44: mq | C44: 0 | D44: 35.7 | E44: =D44*C44 -> 0
A45: Pavimento in laminato antistatico (< 2 kV - UNI EN 1815 ed UNI EN 14041), con supporto di base in fibra di legno ad elevata densità (HDF) con superficie ad effetto legno, resistenza all'abrasione superficiale in classe AC4 (UNI EN 13329), rigonfiamento del bordo ≤ 18% (valore medio 11% UNI EN 13329), resistenza all'impatto in classe IC2 (UNI EN 13329), con incastro sui 4 lati tipo autocentrante per la posa del tipo flottante mediante incollaggio tra gli elementi, in doghe di spessore 9 mm, lunghezza 2.052 mm e larghezza 200 mm | B45: mq | C45: 0 | D45: 31.88 | E45: =D45*C45 -> 0
A46: Unilin sottofondo in schiuma senza barriera vapore | B46: mq | C46: 0 | D46: 1.76 | E46: =D46*C46 -> 0
A47: Tesserine di vetro per pavimenti a tinta unita delle dimensioni 2 × 2 cm, spessore 4 cm, premontate su fogli di carta dimensioni 30 × 30 cm:colori medi | B47: mq | C47: 0 | D47: 63.2 | E47: =D47*C47 -> 0
A48: Moquette in quadrotte autoposanti idonee alla posa senza collante, ad alta flessibilità, antistatiche, ignifughe di classe 1, dimensioni 50 × 50 cm: con supporto in composto termoplastico rinforzato con due strati di fibre di vetro e pretrattato con antibatterico:100% nylon, superficie velluto disegnato, spessore 9,5 mm | B48: mq | C48: 0 | D48: 98.8 | E48: =D48*C48 -> 0
A49: PAVIMENTI PARQUET
A50: Parquet prefinito in listoni composti da uno strato superiore in legno nobile di spessore 5 mm e supporto in multistrato di betulla con profili maschiati:con superficie prelevigata, da finire in opera, spessore totale 14 mm, lunghezza 1.200 ÷ 2.000 mm, larghezza 140 mm:rovere | B50: mq | C50: 0 | D50: 106.25 | E50: =D50*C50 -> 0
A51: Parquet prefinito in listoni composti da uno strato superiore in legno nobile di spessore 5 mm e supporto in multistrato di betulla con profili maschiati:con superficie prelevigata, da finire in opera, spessore totale 10mm, lunghezza 1.200 ÷ 2.000 mm, larghezza 140 mm:rovere | B51: mq | C51: 0 | D51: 106.25 | E51: =D51*C51 -> 0
A52: Parquet prefinito in listoni composti da uno strato superiore in legno nobile di spessore 5 mm e supporto in multistrato di betulla con profili maschiati:con superficie prelevigata, da finire in opera, spessore totale 14 mm, lunghezza 1.200 ÷ 2.000 mm, larghezza 140 mm: teak | B52: mq | C52: 0 | D52: 165.78 | E52: =D52*C52 -> 0
A53: Parquet prefinito in listoni composti da uno strato superiore in legno nobile di spessore 5 mm e supporto in multistrato di betulla con profili maschiati:con superficie prelevigata, da finire in opera, spessore totale 14 mm, lunghezza 1.200 ÷ 2.000 mm, larghezza 140 mm: iroko | B53: mq | C53: 0 | D53: 108.5 | E53: =D53*C53 -> 0
A54: Parquet prefinito in listoni composti da uno strato superiore in legno nobile di spessore 5 mm e supporto in multistrato di betulla con profili maschiati:con superficie prelevigata, da finire in opera, spessore totale 14 mm, lunghezza 1.200 ÷ 2.000 mm, larghezza 140 mm: rovere | B54: mq | C54: 0 | D54: 106.25 | E54: =D54*C54 -> 0
A55: Parquet prefinito in listoni composti da uno strato superiore in legno nobile di spessore 5 mm e supporto in multistrato di betulla con profili maschiati:con superficie prelevigata, da finire in opera, spessore totale 14 mm, lunghezza 1.200 ÷ 2.000 mm, larghezza 140 mm: wengè | B55: mq | C55: 0 | D55: 166.59 | E55: =D55*C55 -> 0
A56: Parquet prefinito in listoni composti da uno strato superiore in legno nobile di spessore 5 mm e supporto in multistrato di betulla con profili maschiati:con superficie prelevigata, da finire in opera, spessore totale 14 mm, lunghezza 1.200 ÷ 2.000 mm, larghezza 140 mm: wengè | B56: mq | C56: 0 | D56: 113.04 | E56: =D56*C56 -> 0
...

Sheet C- SERRAMENTI PORTE  
E3: ='Analisi preliminareTOTALI'!F3 -> Data : 29/05/2025
E4: Validità Preventivo: 15gg
A6: Dati Cliente
A8: ='Analisi preliminareTOTALI'!A8 -> Cliente caso 04
A9: ='Analisi preliminareTOTALI'!A9 -> Indirizzo
A10: ='Analisi preliminareTOTALI'!A10 -> Reggio Emilia (RE)
A11: ='Analisi preliminareTOTALI'!A11 -> 0
A12: ='Analisi preliminareTOTALI'!A12 -> 0
A13: ='Analisi preliminareTOTALI'!A13 -> 0
A15: DESCRIZIONE | B15: UM: | C15: Qta: | D15: Prezzo Unità | E15: Totale
A17: PORTE
A18: Porta interna in legno con anta mobile tamburata e con bordi impiallacciati, completa di telaio maestro in listellare impiallacciato dello spessore di 8/11 mm, coprifili ad incastro in multistrato e tutta la ferramenta necessaria per il fissaggio, movimento e chiusura, delle dimensioni standard di 210 cm × 60-70-80 cm: anta cieca liscia:noce tanganika | B18: cad | C18: 0 | D18: 192.3 | E18: =D18*C18 -> 0
A19: Porta interna in legno con anta mobile tamburata e con bordi impiallacciati, completa di telaio maestro in listellare impiallacciato dello spessore di 8/11 mm, coprifili ad incastro in multistrato e tutta la ferramenta necessaria per il fissaggio, movimento e chiusura, delle dimensioni standard di 210 cm × 60-70-80 cm: anta cieca liscia:laccata bianca | B19: cad | C19: 0 | D19: 271.2 | E19: =D19*C19 -> 0
A20: Montaggio di porte interne a battente misure standard | B20: cad | C20: 0 | D20: 90 | E20: =D20*C20 -> 0
A21: Porta in legno scorrevole interno muro con anta tamburata e bordi impiallacciati, spessore 8/11 mm, coprifili ad incastro in multistrato, serratura a gancio con nottolino e maniglia ad incasso, dimensioni 210 × 60 ÷ 90 cm:cieca liscia, anta singola:noce tanganika | B21: cad | C21: 0 | D21: 380.4 | E21: =D21*C21 -> 0
A22: Porta in legno scorrevole interno muro con anta tamburata e bordi impiallacciati, spessore 8/11 mm, coprifili ad incastro in multistrato, serratura a gancio con nottolino e maniglia ad incasso, dimensioni 210 × 60 ÷ 90 cm:cieca liscia, anta singola:laccata bianca | B22: cad | C22: 0 | D22: 412.2 | E22: =D22*C22 -> 0
A23: Montaggio di porte interne a scomparsa misure standard | B23: cad | C23: 0 | D23: 95 | E23: =D23*C23 -> 0
A24: Porta blindata costituita da telaio in lamiera d'acciaio dello spessore di 20/10 verniciato e predisposto per l'ancoraggio dei bulloni, controtelaio in lamiera dello spessore di 25/10 verniciato con vernice antiruggine, anta in doppia lamiera d'acciaio dello spessore di 12/10 con profili perimetrali d'acciaio dello spessore di 20/10 e profilo rinforzato dal lato della battuta, rivestita in gomma con truciolare di spessore 7 mm circa finitura liscia; completo di occhio magico, guarnizioni su entrambi i lati, serratura principale e di servizio, compasso di sicurezza, isolamento acustico 35 dB, delle seguenti misure:ad un'anta, luce netta 80 ÷ 90 × 210 cm:noce nazionale | B24: cad | C24: 0 | D24: 801.6 | E24: =D24*C24 -> 0
A25: Rimozione vecchio controtelaio e ripristino delle parti ammalorate mediante stuccatura e verciatura delle parti interessate | B25: cad | C25: 0 | D25: 300 | E25: =D25*C25 -> 0
A26: Montaggio di porta blindata mediante montaggio di nuovo controtelaio e assistenza muraria | B26: cad | C26: 0 | D26: 450 | E26: =D26*C26 -> 0
A27: Finestre a 1/2/3 ante con profilo in PVC , telaio SL LA, colore bianco massa, (5 camere con doppia guarnizione), doppio rinforzo, comprensivo di vetro di sicurezza 2.2.1-18GA-22.1BE. Completo di anta a ribalta, microventilazione, ferramenta e maniglia satinata. La voce comprende fornitura, trasporto e montaggio di infisso nuovo su controtelaio vecchio con smontaggio delle vecchie ante e scarico su fronte strada. Compreso il carico da piano strada e trasporto ad impianti di stoccaggio, di recupero o a discarica. NB:il prezzo è da considerarsi puramente indicativo in quanto andrà confermato previo sopralluogo del serramentista eù dopo la scelta della tipologia di serramento adatta alle proprie esigenze. Quadratura minima da considerare: 2mq | B27: mq | C27: 0 | D27: 760 | E27: =D27*C27 -> 0
A28: Porta finestra a 1/2/3 ante con profilo in PVC , telaio SL LA, colore bianco massa, (5 camere con doppia guarnizione), doppio rinforzo, comprensivo di vetro di sicurezza 2.2.1-18GA-22.1BE. Completo di anta a ribalta, microventilazione, ferramenta e maniglia satinata. La voce comprende fornitura, trasporto e montaggio di infisso nuovo su controtelaio vecchio con smontaggio delle vecchie ante e scarico su fronte strada. Compreso il carico da piano strada e trasporto ad impianti di stoccaggio, di recupero o a discarica. NB:il prezzo è da considerarsi puramente indicativo in quanto andrà confermato previo sopralluogo del serramentista eù dopo la scelta della tipologia di serramento adatta alle proprie esigenze Quadratura minima da considerare: 2mq | B28: mq | C28: 0 | D28: 850 | E28: =D28*C28 -> 0
A29: Tapparelle in PVC effetto legno. La voce comprende fornitura, trasporto e montaggio con smontaggio delle vecchie tapparelle e scarico su fronte strada. Compreso il carico da piano strada e trasporto ad impianti di stoccaggio, di recupero o a discarica. NB:il prezzo è da considerarsi puramente indicativo in quanto andrà confermato previo sopralluogo del serramentista e dopo la scelta della tipologia adatta alle proprie esigenze Quadratura minima da considerare: 2mq | B29: mq | C29: 0 | D29: 280 | E29: =D29*C29 -> 0
... A32: Zanzariere a molla orizzontale e/o a catena e/o scorrevole e/o zanzariera a battente. La voce comprende fornitura, trasporto e montaggio NB:il prezzo è da considerarsi puramente indicativo in quanto andrà confermato previo sopralluogo del serramentista e dopo la scelta della tipologia adatta alle proprie esigenze Quadratura minima da considerare: 2mq | B32: mq | C32: 0 | D32: 200 | E32: =D32*C32 -> 0
A33: TOTALE C "PORTE E SERRAMENTI" iva esclusa | E33: =SUM(E18:E32) -> 0
A34: TOTALE C "PORTE E SERRAMENTI iva 10% INCLUSA | E34: =(E33)*1.1 -> 0
A36: Si precisa che il presente documento è idoneo solo a titolo informativo e non costituisce ordinativo e i prezzi potrebbero subire variazioni a seconda del partner selezionato e degli adeguamenti dei listini La scelta definitiva di porte e serramenti andrà finalizzata presso gli show room convenzionati con i nostri partners. Per l'iter da intraprendere vedi allegato "informativa cliente" al contratto di appalto

Sheet D- PRODOTTI
E3: ='Analisi preliminareTOTALI'!F3 -> Data : 29/05/2025
E4: Validità Preventivo: 15gg
A6: Dati Cliente
A8: ='Analisi preliminareTOTALI'!A8 -> Cliente caso 04
A9: ='Analisi preliminareTOTALI'!A9 -> Indirizzo
A10: ='Analisi preliminareTOTALI'!A10 -> Reggio Emilia (RE)
A11: ='Analisi preliminareTOTALI'!A11 -> 0
A12: ='Analisi preliminareTOTALI'!A12 -> 0
A13: ='Analisi preliminareTOTALI'!A13 -> 0
A15: DESCRIZIONE | B15: UM: | C15: Qta: | D15: Prezzo Unità | E15: Totale
A17: PRODOTTI
A18: Fornitura di condizionatore SAMSUNG CEBU monoplit | B18: cad | C18: 0 | D18: 610 | E18: =D18*C18 -> 0
A19: Fornitura di condizionatore SAMSUNG CEBU dualsplit | B19: cad | C19: 0 | D19: 1358 | E19: =D19*C19 -> 0
A20: Fornitura di condizionatore SAMSUNG CEBU trialsplit | B20: cad | C20: 0 | D20: 2025 | E20: =D20*C20 -> 0
A21: Fornitura di condizionatore DAIKIN PREFERA monoplit | B21: cad | C21: 0 | D21: 1276 | E21: =D21*C21 -> 0
A22: Fornitura di condizionatore DAIKIN PREFERA dualsplit | B22: cad | C22: 0 | D22: 2514 | E22: =D22*C22 -> 0
A23: Fornitura di condizionatore DAIKIN PREFERA trialsplit | B23: cad | C23: 0 | D23: 3852 | E23: =D23*C23 -> 0
A24: Fornitura Caldaia MYNUTE RAIN GREEN E 25 | B24: cad | C24: 0 | D24: 1500 | E24: =D24*C24 -> 0
A25: Fornitura scaldabagno TURBO 12L | B25: cad | C25: 0 | D25: 580 | E25: =D25*C25 -> 0
A26: Fornitura di termosifoni tubolari NOVO 1520/500 | B26: cad | C26: 0 | D26: 350 | E26: =D26*C26 -> 0
A27: Fornitura scaldasalviette NOVO | B27: cad | C27: 0 | D27: 198 | E27: =D27*C27 -> 0
A28: TOTALE D "PRODOTTI" iva esclusa | E28: =SUM(E18:E27) -> 0
A29: TOTALE D "PRODOTTI iva 10% INCLUSA | E29: =(E28)*1.1 -> 0
A31: Si precisa che il presente documento è idoneo solo a titolo informativo e non costituisce ordinativo e i prezzi potrebbero subire variazioni a seconda del partner selezionato e degli adeguamenti dei listini La scelta definitiva di materiali e finiture andrà finalizzata presso gli show room convenzionati con i nostri partners.

Sheet listini
A1: Listini
A2: 0.65
A3: 0.6
A4: 0.55
A5: 0.5

Sheet Importi
A1: IMPORTO CAPITOLATO EDILE BHI | G1: ='A-EDILE'!#REF! -> #REF!
A3: IMPORTO EDILE ASSEVERAZIONE | G3: ='A-EDILE'!#REF! -> #REF!
A5: IMPORTO MATERIALI BHI | G5: ='B-FINITURE'!E81 -> 0
A7: IMPORTO MATERIALI ASSEVERAZIONE | G7: ='B-FINITURE'!E81 -> 0
A9: IMPORTO PORTEI BHI | G9: ='C- SERRAMENTI PORTE '!#REF! -> #REF!
A11: IMPORTO PORTE ASSEVERAZIONE | G11: ='C- SERRAMENTI PORTE '!#REF! -> #REF!

Sheet scheda cantiere_EDILE
A1: SCHEDA CANTIERE:
A3: SERVIZIO-EDILE:
A4: CLIENTE: | B4: ='Analisi preliminareTOTALI'!A8 -> Cliente caso 04 | D4: {='Analisi preliminareTOTALI'!A10:B10} -> Reggio Emilia (RE) | E4: 0
A5: CANTIERE: | B5: {='Analisi preliminareTOTALI'!A9:B9} -> Indirizzo | C5: 0 | D5: {='Analisi preliminareTOTALI'!A12:B12} -> 0 | E5: 0
F6: ENTRATE
A7: IMPORTO firmato: | B7: 0 | D7: data fattura | E7: n.
A8: ACCONTO | B8: =(B7/100)*30 -> 0
A9: SAL 1 | B9: =(B7/100)*20 -> 0
A10: SAL2 | B10: =(B7/100)*40 -> 0 | D10: SCONTO IN FATTURA
A11: SALDO | B11: =(B7/100)*10 -> 0 | D11: SCONTO IN FATTURA
A13: EXTRA CAPITOLATO | B13: IMPORTO | D13: data fattura | E13: n.
A14: n.1 | C14: SCONTO IN FATTURA
A15: n.2 | C15: SCONTO IN FATTURA
A16: n.3 | B16: 0
A17: n.4 | B17: 0
A18: ARCHITETTO:
A21: IMPORTO: | B21: =(B7/100)*5 -> 0 | E21: NOTE | F21: USCITE
C22: data fattura | D22: N.
A23: ACCONTO | B23: =(B21/100)*50 -> 0
A24: SALDO | B24: =B21-B23-+((B14/100)*5)+((B15/100)*5)+((B16/100)*5)+((B17/100)*5) -> 0
A26: SUB APPALTO EDILE: | D26: email@esempio.it
D27: 0
A29: IMPORTO: | B29: 325 | E29: NOTE
C30: data fattura | D30: N.
A31: SAL 1 | B31: =(B29/100)*30 -> 97.5
A32: SAL2 | B32: =(B29/100)*30 -> 97.5
A33: SALDO | B33: =(B29/100)*40 -> 130
A34: EXTRA CAPITOLATO | B34: IMPORTO | C34: data fattura | D34: N.
A35: n.1
A36: n.2
A38: SUB APPALTO ELETTRICO :
A41: IMPORTO: | B41: 0 | E41: NOTE
C42: data fattura | D42: N.
A43: SAL 1 | B43: =(B41/100)*30 -> 0
A44: SAL2 | B44: =(B41/100)*30 -> 0
A45: SALDO | B45: =(B41/100)*40 -> 0
A46: EXTRA CAPITOLATO | B46: IMPORTO | C46: data fattura | D46: N.
A47: n.1
A48: n.2
A50: SUB APPALTO IDRAULICO:
...

Sheet scheda cantiere_FINITURE
A1: SCHEDA CANTIERE:
A3: FINITURE:
A4: CLIENTE: | B4: ='scheda cantiere_EDILE'!B4 -> Cliente caso 04 | D4: ='scheda cantiere_EDILE'!D4 -> Reggio Emilia (RE)
A5: CANTIERE: | B5: ='scheda cantiere_EDILE'!B5 -> Indirizzo | D5: ='scheda cantiere_EDILE'!D5 -> 0
F6: ENTRATE
A7: IMPORTO firmato: | B7: 0 | D7: data fattura | E7: N.
A9: SALDO | B9: =B7/2 -> 0
A10: SCONTO IN FATTURA | B10: =B7/2 -> 0
A12: EXTRA CAPITOLATO | B12: IMPORTO
A13: n.1 | B13: 0
A14: n.2 | B14: 0
A15: n.3 | B15: 0
A16: n.4 | B16: 0
A18: ARCHITETTO:
F21: USCITE
A22: IMPORTO: | B22: =(B7/100)*5 -> 0
C23: data fattura | D23: N.
A24: SALDO
A26: FORNITORE:
A30: IMPORTO: | B30: 0
C31: scadenza riba
B32: 0
B33: 0
B34: 0
A38: Legenda | C38: fattura ricevuta in firma
C39: fattura pagata o incassata
C40: fattura ok, in pagamento
G41: =G48/B48 -> #DIV/0!
A42: PREVENTIVI | B42: ENTRATA | C42: USCITE | G42: GUADAGNO
C43: arch. | D43: fornitore
A44: Preventivo 1 | B44: =B7 -> 0 | C44: =B22 -> 0 | D44: =B30 -> 0 | G44: =B44-C44-D44-E44-F44 -> 0
A45: Extra 1 | B45: =B13 -> 0 | C45: =(B45/100)*5 -> 0 | D45: 0 | G45: =B45-C45-D45-E45-F45 -> 0
A46: Extra 2 | B46: =B14 -> 0 | C46: =(B46/100)*5 -> 0 | D46: 0 | G46: =B46-C46-D46-E46-F46 -> 0
B48: =B44+B45+B46 -> 0 | C48: =C44+C45+C46 -> 0 | D48: =D44+D45+D46 -> 0 | G48: =G44+G45+G46 -> 0
